<?xml version="1.0" encoding="utf-8"?>
<!-- This URDF was automatically created by SolidWorks to URDF Exporter! Originally created by Stephen Brawner (brawner@gmail.com) 
     Commit Version: 1.5.1-0-g916b5db  Build Version: 1.5.7152.31018
     For more information, please see http://wiki.ros.org/sw_urdf_exporter -->
<robot
  name="accio_urdf">
  <link
    name="accio_base">
    <inertial>
      <origin
        xyz="2.48458249884497E-17 4.27090944884642E-18 -7.09467145004223E-20"
        rpy="0 0 0" />
      <mass
        value="0.380555680186855" />
      <inertia
        ixx="0.00163354099444434"
        ixy="-4.46857442561865E-19"
        ixz="-1.85388623614183E-24"
        iyy="0.00221639138012642"
        iyz="-1.03858826695855E-22"
        izz="0.00384737488183504" />
    </inertial>
    <visual>
      <origin
        xyz="0 0 0"
        rpy="0 0 0" />
      <geometry>
        <mesh
          filename="package://accio_urdf/meshes/accio_base.STL" />
      </geometry>
      <material
        name="">
        <color
          rgba="0.109803921568627 0.109803921568627 0.109803921568627 1" />
      </material>
    </visual>
    <collision>
      <origin
        xyz="0 0 0"
        rpy="0 0 0" />
      <geometry>
        <mesh
          filename="package://accio_urdf/meshes/accio_base.STL" />
      </geometry>
    </collision>
  </link>
  <link
    name="LF_wheel">
    <inertial>
      <origin
        xyz="1.8392E-07 -0.0058269 -2.9208E-07"
        rpy="0 0 0" />
      <mass
        value="0.62177" />
      <inertia
        ixx="0.00079447"
        ixy="-1.9654E-10"
        ixz="9.3957E-10"
        iyy="0.0013032"
        iyz="-1.8509E-09"
        izz="0.00079447" />
    </inertial>
    <visual>
      <origin
        xyz="0 0 0"
        rpy="0 0 0" />
      <geometry>
        <mesh
          filename="package://accio_urdf/meshes/LF_wheel.STL" />
      </geometry>
      <material
        name="">
        <color
          rgba="0.64706 0.61961 0.6 1" />
      </material>
    </visual>
    <collision>
      <origin
        xyz="0 0 0"
        rpy="0 0 0" />
      <geometry>
        <mesh
          filename="package://accio_urdf/meshes/LF_wheel.STL" />
      </geometry>
    </collision>
  </link>
  <joint
    name="LF_wheel_cont"
    type="continuous">
    <origin
      xyz="0.1143 0.15391 0.019874"
      rpy="0 0 0" />
    <parent
      link="accio_base" />
    <child
      link="LF_wheel" />
    <axis
      xyz="0 1 0" />
    <limit
      lower="0"
      effort="0"
      velocity="100" />
  </joint>
  <link
    name="LR_wheel">
    <inertial>
      <origin
        xyz="1.8392E-07 -0.0058269 -2.9208E-07"
        rpy="0 0 0" />
      <mass
        value="0.62177" />
      <inertia
        ixx="0.00079447"
        ixy="-1.9655E-10"
        ixz="9.3958E-10"
        iyy="0.0013032"
        iyz="-1.8509E-09"
        izz="0.00079448" />
    </inertial>
    <visual>
      <origin
        xyz="0 0 0"
        rpy="0 0 0" />
      <geometry>
        <mesh
          filename="package://accio_urdf/meshes/LR_wheel.STL" />
      </geometry>
      <material
        name="">
        <color
          rgba="0.64706 0.61961 0.6 1" />
      </material>
    </visual>
    <collision>
      <origin
        xyz="0 0 0"
        rpy="0 0 0" />
      <geometry>
        <mesh
          filename="package://accio_urdf/meshes/LR_wheel.STL" />
      </geometry>
    </collision>
  </link>
  <joint
    name="LR_wheel_cont"
    type="continuous">
    <origin
      xyz="-0.1143 0.15391 0.019874"
      rpy="0 0 0" />
    <parent
      link="accio_base" />
    <child
      link="LR_wheel" />
    <axis
      xyz="0 1 0" />
    <limit
      lower="0"
      effort="0"
      velocity="100" />
  </joint>
  <link
    name="RR_wheel">
    <inertial>
      <origin
        xyz="-1.8392E-07 0.0058269 -2.9208E-07"
        rpy="0 0 0" />
      <mass
        value="0.62177" />
      <inertia
        ixx="0.00079447"
        ixy="-1.9655E-10"
        ixz="-9.3956E-10"
        iyy="0.0013032"
        iyz="1.8509E-09"
        izz="0.00079448" />
    </inertial>
    <visual>
      <origin
        xyz="0 0 0"
        rpy="0 0 0" />
      <geometry>
        <mesh
          filename="package://accio_urdf/meshes/RR_wheel.STL" />
      </geometry>
      <material
        name="">
        <color
          rgba="0.64706 0.61961 0.6 1" />
      </material>
    </visual>
    <collision>
      <origin
        xyz="0 0 0"
        rpy="0 0 0" />
      <geometry>
        <mesh
          filename="package://accio_urdf/meshes/RR_wheel.STL" />
      </geometry>
    </collision>
  </link>
  <joint
    name="RR_wheel_cont"
    type="continuous">
    <origin
      xyz="-0.1143 -0.15391 0.019874"
      rpy="0 0 0" />
    <parent
      link="accio_base" />
    <child
      link="RR_wheel" />
    <axis
      xyz="0 -1 0" />
    <limit
      lower="0"
      effort="0"
      velocity="100" />
  </joint>
  <link
    name="RF_wheel">
    <inertial>
      <origin
        xyz="-1.8392E-07 0.0058269 -2.9208E-07"
        rpy="0 0 0" />
      <mass
        value="0.62177" />
      <inertia
        ixx="0.00079447"
        ixy="-1.9655E-10"
        ixz="-9.3956E-10"
        iyy="0.0013032"
        iyz="1.8509E-09"
        izz="0.00079448" />
    </inertial>
    <visual>
      <origin
        xyz="0 0 0"
        rpy="0 0 0" />
      <geometry>
        <mesh
          filename="package://accio_urdf/meshes/RF_wheel.STL" />
      </geometry>
      <material
        name="">
        <color
          rgba="0.64706 0.61961 0.6 1" />
      </material>
    </visual>
    <collision>
      <origin
        xyz="0 0 0"
        rpy="0 0 0" />
      <geometry>
        <mesh
          filename="package://accio_urdf/meshes/RF_wheel.STL" />
      </geometry>
    </collision>
  </link>
  <joint
    name="RF_wheel_cont"
    type="continuous">
    <origin
      xyz="0.1143 -0.15391 0.019874"
      rpy="0 0 0" />
    <parent
      link="accio_base" />
    <child
      link="RF_wheel" />
    <axis
      xyz="0 -1 0" />
    <limit
      lower="0"
      effort="0"
      velocity="100" />
  </joint>
</robot>